[2024-06-13T00:00:25.208+0000] {processor.py:157} INFO - Started process (PID=986) to work on /opt/airflow/dags/data_etl_dag.py
[2024-06-13T00:00:25.208+0000] {processor.py:829} INFO - Processing file /opt/airflow/dags/data_etl_dag.py for tasks to queue
[2024-06-13T00:00:25.209+0000] {logging_mixin.py:151} INFO - [2024-06-13T00:00:25.209+0000] {dagbag.py:536} INFO - Filling up the DagBag from /opt/airflow/dags/data_etl_dag.py
[2024-06-13T00:00:25.240+0000] {logging_mixin.py:151} INFO - [2024-06-13T00:00:25.237+0000] {dagbag.py:346} ERROR - Failed to import: /opt/airflow/dags/data_etl_dag.py
Traceback (most recent call last):
  File "/home/airflow/.local/lib/python3.8/site-packages/airflow/models/dagbag.py", line 342, in parse
    loader.exec_module(new_module)
  File "<frozen importlib._bootstrap_external>", line 843, in exec_module
  File "<frozen importlib._bootstrap>", line 219, in _call_with_frames_removed
  File "/opt/airflow/dags/data_etl_dag.py", line 7, in <module>
    from tasks.parse_hh import get_dataset_with_tags
  File "/opt/airflow/dags/tasks/parse_hh.py", line 3, in <module>
    import fake_useragent
ModuleNotFoundError: No module named 'fake_useragent'
[2024-06-13T00:00:25.241+0000] {processor.py:841} WARNING - No viable dags retrieved from /opt/airflow/dags/data_etl_dag.py
[2024-06-13T00:00:25.252+0000] {processor.py:179} INFO - Processing /opt/airflow/dags/data_etl_dag.py took 0.046 seconds
[2024-06-13T00:00:55.383+0000] {processor.py:157} INFO - Started process (PID=998) to work on /opt/airflow/dags/data_etl_dag.py
[2024-06-13T00:00:55.384+0000] {processor.py:829} INFO - Processing file /opt/airflow/dags/data_etl_dag.py for tasks to queue
[2024-06-13T00:00:55.384+0000] {logging_mixin.py:151} INFO - [2024-06-13T00:00:55.384+0000] {dagbag.py:536} INFO - Filling up the DagBag from /opt/airflow/dags/data_etl_dag.py
[2024-06-13T00:00:55.421+0000] {logging_mixin.py:151} INFO - [2024-06-13T00:00:55.417+0000] {dagbag.py:346} ERROR - Failed to import: /opt/airflow/dags/data_etl_dag.py
Traceback (most recent call last):
  File "/home/airflow/.local/lib/python3.8/site-packages/airflow/models/dagbag.py", line 342, in parse
    loader.exec_module(new_module)
  File "<frozen importlib._bootstrap_external>", line 843, in exec_module
  File "<frozen importlib._bootstrap>", line 219, in _call_with_frames_removed
  File "/opt/airflow/dags/data_etl_dag.py", line 7, in <module>
    from tasks.parse_hh import get_dataset_with_tags
  File "/opt/airflow/dags/tasks/parse_hh.py", line 3, in <module>
    import fake_useragent
ModuleNotFoundError: No module named 'fake_useragent'
[2024-06-13T00:00:55.422+0000] {processor.py:841} WARNING - No viable dags retrieved from /opt/airflow/dags/data_etl_dag.py
[2024-06-13T00:00:55.433+0000] {processor.py:179} INFO - Processing /opt/airflow/dags/data_etl_dag.py took 0.051 seconds
[2024-06-13T00:01:25.528+0000] {processor.py:157} INFO - Started process (PID=1010) to work on /opt/airflow/dags/data_etl_dag.py
[2024-06-13T00:01:25.529+0000] {processor.py:829} INFO - Processing file /opt/airflow/dags/data_etl_dag.py for tasks to queue
[2024-06-13T00:01:25.529+0000] {logging_mixin.py:151} INFO - [2024-06-13T00:01:25.529+0000] {dagbag.py:536} INFO - Filling up the DagBag from /opt/airflow/dags/data_etl_dag.py
[2024-06-13T00:01:25.556+0000] {logging_mixin.py:151} INFO - [2024-06-13T00:01:25.553+0000] {dagbag.py:346} ERROR - Failed to import: /opt/airflow/dags/data_etl_dag.py
Traceback (most recent call last):
  File "/home/airflow/.local/lib/python3.8/site-packages/airflow/models/dagbag.py", line 342, in parse
    loader.exec_module(new_module)
  File "<frozen importlib._bootstrap_external>", line 843, in exec_module
  File "<frozen importlib._bootstrap>", line 219, in _call_with_frames_removed
  File "/opt/airflow/dags/data_etl_dag.py", line 7, in <module>
    from tasks.parse_hh import get_dataset_with_tags
  File "/opt/airflow/dags/tasks/parse_hh.py", line 3, in <module>
    import fake_useragent
ModuleNotFoundError: No module named 'fake_useragent'
[2024-06-13T00:01:25.557+0000] {processor.py:841} WARNING - No viable dags retrieved from /opt/airflow/dags/data_etl_dag.py
[2024-06-13T00:01:25.569+0000] {processor.py:179} INFO - Processing /opt/airflow/dags/data_etl_dag.py took 0.042 seconds
[2024-06-13T00:01:55.864+0000] {processor.py:157} INFO - Started process (PID=1022) to work on /opt/airflow/dags/data_etl_dag.py
[2024-06-13T00:01:55.865+0000] {processor.py:829} INFO - Processing file /opt/airflow/dags/data_etl_dag.py for tasks to queue
[2024-06-13T00:01:55.865+0000] {logging_mixin.py:151} INFO - [2024-06-13T00:01:55.865+0000] {dagbag.py:536} INFO - Filling up the DagBag from /opt/airflow/dags/data_etl_dag.py
[2024-06-13T00:01:55.891+0000] {logging_mixin.py:151} INFO - [2024-06-13T00:01:55.889+0000] {dagbag.py:346} ERROR - Failed to import: /opt/airflow/dags/data_etl_dag.py
Traceback (most recent call last):
  File "/home/airflow/.local/lib/python3.8/site-packages/airflow/models/dagbag.py", line 342, in parse
    loader.exec_module(new_module)
  File "<frozen importlib._bootstrap_external>", line 843, in exec_module
  File "<frozen importlib._bootstrap>", line 219, in _call_with_frames_removed
  File "/opt/airflow/dags/data_etl_dag.py", line 7, in <module>
    from tasks.parse_hh import get_dataset_with_tags
  File "/opt/airflow/dags/tasks/parse_hh.py", line 3, in <module>
    import fake_useragent
ModuleNotFoundError: No module named 'fake_useragent'
[2024-06-13T00:01:55.892+0000] {processor.py:841} WARNING - No viable dags retrieved from /opt/airflow/dags/data_etl_dag.py
[2024-06-13T00:01:55.904+0000] {processor.py:179} INFO - Processing /opt/airflow/dags/data_etl_dag.py took 0.042 seconds
[2024-06-13T00:02:25.992+0000] {processor.py:157} INFO - Started process (PID=1034) to work on /opt/airflow/dags/data_etl_dag.py
[2024-06-13T00:02:25.993+0000] {processor.py:829} INFO - Processing file /opt/airflow/dags/data_etl_dag.py for tasks to queue
[2024-06-13T00:02:25.994+0000] {logging_mixin.py:151} INFO - [2024-06-13T00:02:25.993+0000] {dagbag.py:536} INFO - Filling up the DagBag from /opt/airflow/dags/data_etl_dag.py
[2024-06-13T00:02:26.019+0000] {logging_mixin.py:151} INFO - [2024-06-13T00:02:26.016+0000] {dagbag.py:346} ERROR - Failed to import: /opt/airflow/dags/data_etl_dag.py
Traceback (most recent call last):
  File "/home/airflow/.local/lib/python3.8/site-packages/airflow/models/dagbag.py", line 342, in parse
    loader.exec_module(new_module)
  File "<frozen importlib._bootstrap_external>", line 843, in exec_module
  File "<frozen importlib._bootstrap>", line 219, in _call_with_frames_removed
  File "/opt/airflow/dags/data_etl_dag.py", line 7, in <module>
    from tasks.parse_hh import get_dataset_with_tags
  File "/opt/airflow/dags/tasks/parse_hh.py", line 3, in <module>
    import fake_useragent
ModuleNotFoundError: No module named 'fake_useragent'
[2024-06-13T00:02:26.020+0000] {processor.py:841} WARNING - No viable dags retrieved from /opt/airflow/dags/data_etl_dag.py
[2024-06-13T00:02:26.033+0000] {processor.py:179} INFO - Processing /opt/airflow/dags/data_etl_dag.py took 0.043 seconds
[2024-06-13T00:02:56.161+0000] {processor.py:157} INFO - Started process (PID=1046) to work on /opt/airflow/dags/data_etl_dag.py
[2024-06-13T00:02:56.161+0000] {processor.py:829} INFO - Processing file /opt/airflow/dags/data_etl_dag.py for tasks to queue
[2024-06-13T00:02:56.162+0000] {logging_mixin.py:151} INFO - [2024-06-13T00:02:56.162+0000] {dagbag.py:536} INFO - Filling up the DagBag from /opt/airflow/dags/data_etl_dag.py
[2024-06-13T00:02:56.187+0000] {logging_mixin.py:151} INFO - [2024-06-13T00:02:56.184+0000] {dagbag.py:346} ERROR - Failed to import: /opt/airflow/dags/data_etl_dag.py
Traceback (most recent call last):
  File "/home/airflow/.local/lib/python3.8/site-packages/airflow/models/dagbag.py", line 342, in parse
    loader.exec_module(new_module)
  File "<frozen importlib._bootstrap_external>", line 843, in exec_module
  File "<frozen importlib._bootstrap>", line 219, in _call_with_frames_removed
  File "/opt/airflow/dags/data_etl_dag.py", line 7, in <module>
    from tasks.parse_hh import get_dataset_with_tags
  File "/opt/airflow/dags/tasks/parse_hh.py", line 3, in <module>
    import fake_useragent
ModuleNotFoundError: No module named 'fake_useragent'
[2024-06-13T00:02:56.188+0000] {processor.py:841} WARNING - No viable dags retrieved from /opt/airflow/dags/data_etl_dag.py
[2024-06-13T00:02:56.200+0000] {processor.py:179} INFO - Processing /opt/airflow/dags/data_etl_dag.py took 0.041 seconds
[2024-06-13T00:03:26.314+0000] {processor.py:157} INFO - Started process (PID=1058) to work on /opt/airflow/dags/data_etl_dag.py
[2024-06-13T00:03:26.314+0000] {processor.py:829} INFO - Processing file /opt/airflow/dags/data_etl_dag.py for tasks to queue
[2024-06-13T00:03:26.315+0000] {logging_mixin.py:151} INFO - [2024-06-13T00:03:26.315+0000] {dagbag.py:536} INFO - Filling up the DagBag from /opt/airflow/dags/data_etl_dag.py
[2024-06-13T00:03:26.341+0000] {logging_mixin.py:151} INFO - [2024-06-13T00:03:26.338+0000] {dagbag.py:346} ERROR - Failed to import: /opt/airflow/dags/data_etl_dag.py
Traceback (most recent call last):
  File "/home/airflow/.local/lib/python3.8/site-packages/airflow/models/dagbag.py", line 342, in parse
    loader.exec_module(new_module)
  File "<frozen importlib._bootstrap_external>", line 843, in exec_module
  File "<frozen importlib._bootstrap>", line 219, in _call_with_frames_removed
  File "/opt/airflow/dags/data_etl_dag.py", line 7, in <module>
    from tasks.parse_hh import get_dataset_with_tags
  File "/opt/airflow/dags/tasks/parse_hh.py", line 3, in <module>
    import fake_useragent
ModuleNotFoundError: No module named 'fake_useragent'
[2024-06-13T00:03:26.342+0000] {processor.py:841} WARNING - No viable dags retrieved from /opt/airflow/dags/data_etl_dag.py
[2024-06-13T00:03:26.354+0000] {processor.py:179} INFO - Processing /opt/airflow/dags/data_etl_dag.py took 0.042 seconds
[2024-06-13T00:03:56.461+0000] {processor.py:157} INFO - Started process (PID=1070) to work on /opt/airflow/dags/data_etl_dag.py
[2024-06-13T00:03:56.462+0000] {processor.py:829} INFO - Processing file /opt/airflow/dags/data_etl_dag.py for tasks to queue
[2024-06-13T00:03:56.462+0000] {logging_mixin.py:151} INFO - [2024-06-13T00:03:56.462+0000] {dagbag.py:536} INFO - Filling up the DagBag from /opt/airflow/dags/data_etl_dag.py
[2024-06-13T00:03:56.488+0000] {logging_mixin.py:151} INFO - [2024-06-13T00:03:56.486+0000] {dagbag.py:346} ERROR - Failed to import: /opt/airflow/dags/data_etl_dag.py
Traceback (most recent call last):
  File "/home/airflow/.local/lib/python3.8/site-packages/airflow/models/dagbag.py", line 342, in parse
    loader.exec_module(new_module)
  File "<frozen importlib._bootstrap_external>", line 843, in exec_module
  File "<frozen importlib._bootstrap>", line 219, in _call_with_frames_removed
  File "/opt/airflow/dags/data_etl_dag.py", line 7, in <module>
    from tasks.parse_hh import get_dataset_with_tags
  File "/opt/airflow/dags/tasks/parse_hh.py", line 3, in <module>
    import fake_useragent
ModuleNotFoundError: No module named 'fake_useragent'
[2024-06-13T00:03:56.489+0000] {processor.py:841} WARNING - No viable dags retrieved from /opt/airflow/dags/data_etl_dag.py
[2024-06-13T00:03:56.503+0000] {processor.py:179} INFO - Processing /opt/airflow/dags/data_etl_dag.py took 0.044 seconds
[2024-06-13T00:04:26.604+0000] {processor.py:157} INFO - Started process (PID=1082) to work on /opt/airflow/dags/data_etl_dag.py
[2024-06-13T00:04:26.605+0000] {processor.py:829} INFO - Processing file /opt/airflow/dags/data_etl_dag.py for tasks to queue
[2024-06-13T00:04:26.606+0000] {logging_mixin.py:151} INFO - [2024-06-13T00:04:26.605+0000] {dagbag.py:536} INFO - Filling up the DagBag from /opt/airflow/dags/data_etl_dag.py
[2024-06-13T00:04:26.687+0000] {logging_mixin.py:151} INFO - [2024-06-13T00:04:26.682+0000] {dagbag.py:346} ERROR - Failed to import: /opt/airflow/dags/data_etl_dag.py
Traceback (most recent call last):
  File "/home/airflow/.local/lib/python3.8/site-packages/airflow/models/dagbag.py", line 342, in parse
    loader.exec_module(new_module)
  File "<frozen importlib._bootstrap_external>", line 843, in exec_module
  File "<frozen importlib._bootstrap>", line 219, in _call_with_frames_removed
  File "/opt/airflow/dags/data_etl_dag.py", line 7, in <module>
    from tasks.parse_hh import get_dataset_with_tags
  File "/opt/airflow/dags/tasks/parse_hh.py", line 3, in <module>
    import fake_useragent
ModuleNotFoundError: No module named 'fake_useragent'
[2024-06-13T00:04:26.688+0000] {processor.py:841} WARNING - No viable dags retrieved from /opt/airflow/dags/data_etl_dag.py
[2024-06-13T00:04:26.702+0000] {processor.py:179} INFO - Processing /opt/airflow/dags/data_etl_dag.py took 0.100 seconds
[2024-06-13T00:04:56.736+0000] {processor.py:157} INFO - Started process (PID=1094) to work on /opt/airflow/dags/data_etl_dag.py
[2024-06-13T00:04:56.737+0000] {processor.py:829} INFO - Processing file /opt/airflow/dags/data_etl_dag.py for tasks to queue
[2024-06-13T00:04:56.738+0000] {logging_mixin.py:151} INFO - [2024-06-13T00:04:56.737+0000] {dagbag.py:536} INFO - Filling up the DagBag from /opt/airflow/dags/data_etl_dag.py
[2024-06-13T00:04:56.764+0000] {logging_mixin.py:151} INFO - [2024-06-13T00:04:56.762+0000] {dagbag.py:346} ERROR - Failed to import: /opt/airflow/dags/data_etl_dag.py
Traceback (most recent call last):
  File "/home/airflow/.local/lib/python3.8/site-packages/airflow/models/dagbag.py", line 342, in parse
    loader.exec_module(new_module)
  File "<frozen importlib._bootstrap_external>", line 843, in exec_module
  File "<frozen importlib._bootstrap>", line 219, in _call_with_frames_removed
  File "/opt/airflow/dags/data_etl_dag.py", line 7, in <module>
    from tasks.parse_hh import get_dataset_with_tags
  File "/opt/airflow/dags/tasks/parse_hh.py", line 3, in <module>
    import fake_useragent
ModuleNotFoundError: No module named 'fake_useragent'
[2024-06-13T00:04:56.765+0000] {processor.py:841} WARNING - No viable dags retrieved from /opt/airflow/dags/data_etl_dag.py
[2024-06-13T00:04:56.778+0000] {processor.py:179} INFO - Processing /opt/airflow/dags/data_etl_dag.py took 0.043 seconds
[2024-06-13T00:05:26.853+0000] {processor.py:157} INFO - Started process (PID=1106) to work on /opt/airflow/dags/data_etl_dag.py
[2024-06-13T00:05:26.854+0000] {processor.py:829} INFO - Processing file /opt/airflow/dags/data_etl_dag.py for tasks to queue
[2024-06-13T00:05:26.855+0000] {logging_mixin.py:151} INFO - [2024-06-13T00:05:26.855+0000] {dagbag.py:536} INFO - Filling up the DagBag from /opt/airflow/dags/data_etl_dag.py
[2024-06-13T00:05:26.891+0000] {logging_mixin.py:151} INFO - [2024-06-13T00:05:26.887+0000] {dagbag.py:346} ERROR - Failed to import: /opt/airflow/dags/data_etl_dag.py
Traceback (most recent call last):
  File "/home/airflow/.local/lib/python3.8/site-packages/airflow/models/dagbag.py", line 342, in parse
    loader.exec_module(new_module)
  File "<frozen importlib._bootstrap_external>", line 843, in exec_module
  File "<frozen importlib._bootstrap>", line 219, in _call_with_frames_removed
  File "/opt/airflow/dags/data_etl_dag.py", line 7, in <module>
    from tasks.parse_hh import get_dataset_with_tags
  File "/opt/airflow/dags/tasks/parse_hh.py", line 3, in <module>
    import fake_useragent
ModuleNotFoundError: No module named 'fake_useragent'
[2024-06-13T00:05:26.892+0000] {processor.py:841} WARNING - No viable dags retrieved from /opt/airflow/dags/data_etl_dag.py
[2024-06-13T00:05:26.905+0000] {processor.py:179} INFO - Processing /opt/airflow/dags/data_etl_dag.py took 0.053 seconds
[2024-06-13T00:05:57.027+0000] {processor.py:157} INFO - Started process (PID=1118) to work on /opt/airflow/dags/data_etl_dag.py
[2024-06-13T00:05:57.027+0000] {processor.py:829} INFO - Processing file /opt/airflow/dags/data_etl_dag.py for tasks to queue
[2024-06-13T00:05:57.028+0000] {logging_mixin.py:151} INFO - [2024-06-13T00:05:57.028+0000] {dagbag.py:536} INFO - Filling up the DagBag from /opt/airflow/dags/data_etl_dag.py
[2024-06-13T00:05:57.055+0000] {logging_mixin.py:151} INFO - [2024-06-13T00:05:57.052+0000] {dagbag.py:346} ERROR - Failed to import: /opt/airflow/dags/data_etl_dag.py
Traceback (most recent call last):
  File "/home/airflow/.local/lib/python3.8/site-packages/airflow/models/dagbag.py", line 342, in parse
    loader.exec_module(new_module)
  File "<frozen importlib._bootstrap_external>", line 843, in exec_module
  File "<frozen importlib._bootstrap>", line 219, in _call_with_frames_removed
  File "/opt/airflow/dags/data_etl_dag.py", line 7, in <module>
    from tasks.parse_hh import get_dataset_with_tags
  File "/opt/airflow/dags/tasks/parse_hh.py", line 3, in <module>
    import fake_useragent
ModuleNotFoundError: No module named 'fake_useragent'
[2024-06-13T00:05:57.056+0000] {processor.py:841} WARNING - No viable dags retrieved from /opt/airflow/dags/data_etl_dag.py
[2024-06-13T00:05:57.068+0000] {processor.py:179} INFO - Processing /opt/airflow/dags/data_etl_dag.py took 0.043 seconds
[2024-06-13T00:06:27.162+0000] {processor.py:157} INFO - Started process (PID=1130) to work on /opt/airflow/dags/data_etl_dag.py
[2024-06-13T00:06:27.164+0000] {processor.py:829} INFO - Processing file /opt/airflow/dags/data_etl_dag.py for tasks to queue
[2024-06-13T00:06:27.167+0000] {logging_mixin.py:151} INFO - [2024-06-13T00:06:27.167+0000] {dagbag.py:536} INFO - Filling up the DagBag from /opt/airflow/dags/data_etl_dag.py
[2024-06-13T00:06:27.202+0000] {logging_mixin.py:151} INFO - [2024-06-13T00:06:27.199+0000] {dagbag.py:346} ERROR - Failed to import: /opt/airflow/dags/data_etl_dag.py
Traceback (most recent call last):
  File "/home/airflow/.local/lib/python3.8/site-packages/airflow/models/dagbag.py", line 342, in parse
    loader.exec_module(new_module)
  File "<frozen importlib._bootstrap_external>", line 843, in exec_module
  File "<frozen importlib._bootstrap>", line 219, in _call_with_frames_removed
  File "/opt/airflow/dags/data_etl_dag.py", line 7, in <module>
    from tasks.parse_hh import get_dataset_with_tags
  File "/opt/airflow/dags/tasks/parse_hh.py", line 3, in <module>
    import fake_useragent
ModuleNotFoundError: No module named 'fake_useragent'
[2024-06-13T00:06:27.203+0000] {processor.py:841} WARNING - No viable dags retrieved from /opt/airflow/dags/data_etl_dag.py
[2024-06-13T00:06:27.219+0000] {processor.py:179} INFO - Processing /opt/airflow/dags/data_etl_dag.py took 0.058 seconds
[2024-06-13T00:06:57.507+0000] {processor.py:157} INFO - Started process (PID=1142) to work on /opt/airflow/dags/data_etl_dag.py
[2024-06-13T00:06:57.507+0000] {processor.py:829} INFO - Processing file /opt/airflow/dags/data_etl_dag.py for tasks to queue
[2024-06-13T00:06:57.508+0000] {logging_mixin.py:151} INFO - [2024-06-13T00:06:57.508+0000] {dagbag.py:536} INFO - Filling up the DagBag from /opt/airflow/dags/data_etl_dag.py
[2024-06-13T00:06:57.535+0000] {logging_mixin.py:151} INFO - [2024-06-13T00:06:57.533+0000] {dagbag.py:346} ERROR - Failed to import: /opt/airflow/dags/data_etl_dag.py
Traceback (most recent call last):
  File "/home/airflow/.local/lib/python3.8/site-packages/airflow/models/dagbag.py", line 342, in parse
    loader.exec_module(new_module)
  File "<frozen importlib._bootstrap_external>", line 843, in exec_module
  File "<frozen importlib._bootstrap>", line 219, in _call_with_frames_removed
  File "/opt/airflow/dags/data_etl_dag.py", line 7, in <module>
    from tasks.parse_hh import get_dataset_with_tags
  File "/opt/airflow/dags/tasks/parse_hh.py", line 3, in <module>
    import fake_useragent
ModuleNotFoundError: No module named 'fake_useragent'
[2024-06-13T00:06:57.536+0000] {processor.py:841} WARNING - No viable dags retrieved from /opt/airflow/dags/data_etl_dag.py
[2024-06-13T00:06:57.548+0000] {processor.py:179} INFO - Processing /opt/airflow/dags/data_etl_dag.py took 0.043 seconds
[2024-06-13T00:07:27.655+0000] {processor.py:157} INFO - Started process (PID=1154) to work on /opt/airflow/dags/data_etl_dag.py
[2024-06-13T00:07:27.655+0000] {processor.py:829} INFO - Processing file /opt/airflow/dags/data_etl_dag.py for tasks to queue
[2024-06-13T00:07:27.656+0000] {logging_mixin.py:151} INFO - [2024-06-13T00:07:27.656+0000] {dagbag.py:536} INFO - Filling up the DagBag from /opt/airflow/dags/data_etl_dag.py
[2024-06-13T00:07:27.691+0000] {logging_mixin.py:151} INFO - [2024-06-13T00:07:27.688+0000] {dagbag.py:346} ERROR - Failed to import: /opt/airflow/dags/data_etl_dag.py
Traceback (most recent call last):
  File "/home/airflow/.local/lib/python3.8/site-packages/airflow/models/dagbag.py", line 342, in parse
    loader.exec_module(new_module)
  File "<frozen importlib._bootstrap_external>", line 843, in exec_module
  File "<frozen importlib._bootstrap>", line 219, in _call_with_frames_removed
  File "/opt/airflow/dags/data_etl_dag.py", line 7, in <module>
    from tasks.parse_hh import get_dataset_with_tags
  File "/opt/airflow/dags/tasks/parse_hh.py", line 3, in <module>
    import fake_useragent
ModuleNotFoundError: No module named 'fake_useragent'
[2024-06-13T00:07:27.692+0000] {processor.py:841} WARNING - No viable dags retrieved from /opt/airflow/dags/data_etl_dag.py
[2024-06-13T00:07:27.703+0000] {processor.py:179} INFO - Processing /opt/airflow/dags/data_etl_dag.py took 0.050 seconds
[2024-06-13T00:07:57.788+0000] {processor.py:157} INFO - Started process (PID=1167) to work on /opt/airflow/dags/data_etl_dag.py
[2024-06-13T00:07:57.788+0000] {processor.py:829} INFO - Processing file /opt/airflow/dags/data_etl_dag.py for tasks to queue
[2024-06-13T00:07:57.789+0000] {logging_mixin.py:151} INFO - [2024-06-13T00:07:57.789+0000] {dagbag.py:536} INFO - Filling up the DagBag from /opt/airflow/dags/data_etl_dag.py
[2024-06-13T00:07:57.816+0000] {logging_mixin.py:151} INFO - [2024-06-13T00:07:57.812+0000] {dagbag.py:346} ERROR - Failed to import: /opt/airflow/dags/data_etl_dag.py
Traceback (most recent call last):
  File "/home/airflow/.local/lib/python3.8/site-packages/airflow/models/dagbag.py", line 342, in parse
    loader.exec_module(new_module)
  File "<frozen importlib._bootstrap_external>", line 843, in exec_module
  File "<frozen importlib._bootstrap>", line 219, in _call_with_frames_removed
  File "/opt/airflow/dags/data_etl_dag.py", line 7, in <module>
    from tasks.parse_hh import get_dataset_with_tags
  File "/opt/airflow/dags/tasks/parse_hh.py", line 3, in <module>
    import fake_useragent
ModuleNotFoundError: No module named 'fake_useragent'
[2024-06-13T00:07:57.817+0000] {processor.py:841} WARNING - No viable dags retrieved from /opt/airflow/dags/data_etl_dag.py
[2024-06-13T00:07:57.828+0000] {processor.py:179} INFO - Processing /opt/airflow/dags/data_etl_dag.py took 0.042 seconds
[2024-06-13T00:08:27.964+0000] {processor.py:157} INFO - Started process (PID=1179) to work on /opt/airflow/dags/data_etl_dag.py
[2024-06-13T00:08:27.965+0000] {processor.py:829} INFO - Processing file /opt/airflow/dags/data_etl_dag.py for tasks to queue
[2024-06-13T00:08:27.965+0000] {logging_mixin.py:151} INFO - [2024-06-13T00:08:27.965+0000] {dagbag.py:536} INFO - Filling up the DagBag from /opt/airflow/dags/data_etl_dag.py
[2024-06-13T00:08:27.992+0000] {logging_mixin.py:151} INFO - [2024-06-13T00:08:27.989+0000] {dagbag.py:346} ERROR - Failed to import: /opt/airflow/dags/data_etl_dag.py
Traceback (most recent call last):
  File "/home/airflow/.local/lib/python3.8/site-packages/airflow/models/dagbag.py", line 342, in parse
    loader.exec_module(new_module)
  File "<frozen importlib._bootstrap_external>", line 843, in exec_module
  File "<frozen importlib._bootstrap>", line 219, in _call_with_frames_removed
  File "/opt/airflow/dags/data_etl_dag.py", line 7, in <module>
    from tasks.parse_hh import get_dataset_with_tags
  File "/opt/airflow/dags/tasks/parse_hh.py", line 3, in <module>
    import fake_useragent
ModuleNotFoundError: No module named 'fake_useragent'
[2024-06-13T00:08:27.993+0000] {processor.py:841} WARNING - No viable dags retrieved from /opt/airflow/dags/data_etl_dag.py
[2024-06-13T00:08:28.046+0000] {processor.py:179} INFO - Processing /opt/airflow/dags/data_etl_dag.py took 0.084 seconds
[2024-06-13T00:08:58.085+0000] {processor.py:157} INFO - Started process (PID=1191) to work on /opt/airflow/dags/data_etl_dag.py
[2024-06-13T00:08:58.086+0000] {processor.py:829} INFO - Processing file /opt/airflow/dags/data_etl_dag.py for tasks to queue
[2024-06-13T00:08:58.086+0000] {logging_mixin.py:151} INFO - [2024-06-13T00:08:58.086+0000] {dagbag.py:536} INFO - Filling up the DagBag from /opt/airflow/dags/data_etl_dag.py
[2024-06-13T00:08:58.114+0000] {logging_mixin.py:151} INFO - [2024-06-13T00:08:58.112+0000] {dagbag.py:346} ERROR - Failed to import: /opt/airflow/dags/data_etl_dag.py
Traceback (most recent call last):
  File "/home/airflow/.local/lib/python3.8/site-packages/airflow/models/dagbag.py", line 342, in parse
    loader.exec_module(new_module)
  File "<frozen importlib._bootstrap_external>", line 843, in exec_module
  File "<frozen importlib._bootstrap>", line 219, in _call_with_frames_removed
  File "/opt/airflow/dags/data_etl_dag.py", line 7, in <module>
    from tasks.parse_hh import get_dataset_with_tags
  File "/opt/airflow/dags/tasks/parse_hh.py", line 3, in <module>
    import fake_useragent
ModuleNotFoundError: No module named 'fake_useragent'
[2024-06-13T00:08:58.115+0000] {processor.py:841} WARNING - No viable dags retrieved from /opt/airflow/dags/data_etl_dag.py
[2024-06-13T00:08:58.127+0000] {processor.py:179} INFO - Processing /opt/airflow/dags/data_etl_dag.py took 0.044 seconds
[2024-06-13T00:09:28.327+0000] {processor.py:157} INFO - Started process (PID=1204) to work on /opt/airflow/dags/data_etl_dag.py
[2024-06-13T00:09:28.327+0000] {processor.py:829} INFO - Processing file /opt/airflow/dags/data_etl_dag.py for tasks to queue
[2024-06-13T00:09:28.328+0000] {logging_mixin.py:151} INFO - [2024-06-13T00:09:28.328+0000] {dagbag.py:536} INFO - Filling up the DagBag from /opt/airflow/dags/data_etl_dag.py
[2024-06-13T00:09:28.355+0000] {logging_mixin.py:151} INFO - [2024-06-13T00:09:28.352+0000] {dagbag.py:346} ERROR - Failed to import: /opt/airflow/dags/data_etl_dag.py
Traceback (most recent call last):
  File "/home/airflow/.local/lib/python3.8/site-packages/airflow/models/dagbag.py", line 342, in parse
    loader.exec_module(new_module)
  File "<frozen importlib._bootstrap_external>", line 843, in exec_module
  File "<frozen importlib._bootstrap>", line 219, in _call_with_frames_removed
  File "/opt/airflow/dags/data_etl_dag.py", line 7, in <module>
    from tasks.parse_hh import get_dataset_with_tags
  File "/opt/airflow/dags/tasks/parse_hh.py", line 3, in <module>
    import fake_useragent
ModuleNotFoundError: No module named 'fake_useragent'
[2024-06-13T00:09:28.356+0000] {processor.py:841} WARNING - No viable dags retrieved from /opt/airflow/dags/data_etl_dag.py
[2024-06-13T00:09:28.368+0000] {processor.py:179} INFO - Processing /opt/airflow/dags/data_etl_dag.py took 0.043 seconds
[2024-06-13T00:09:58.454+0000] {processor.py:157} INFO - Started process (PID=1216) to work on /opt/airflow/dags/data_etl_dag.py
[2024-06-13T00:09:58.455+0000] {processor.py:829} INFO - Processing file /opt/airflow/dags/data_etl_dag.py for tasks to queue
[2024-06-13T00:09:58.456+0000] {logging_mixin.py:151} INFO - [2024-06-13T00:09:58.455+0000] {dagbag.py:536} INFO - Filling up the DagBag from /opt/airflow/dags/data_etl_dag.py
[2024-06-13T00:09:58.507+0000] {logging_mixin.py:151} INFO - [2024-06-13T00:09:58.504+0000] {dagbag.py:346} ERROR - Failed to import: /opt/airflow/dags/data_etl_dag.py
Traceback (most recent call last):
  File "/home/airflow/.local/lib/python3.8/site-packages/airflow/models/dagbag.py", line 342, in parse
    loader.exec_module(new_module)
  File "<frozen importlib._bootstrap_external>", line 843, in exec_module
  File "<frozen importlib._bootstrap>", line 219, in _call_with_frames_removed
  File "/opt/airflow/dags/data_etl_dag.py", line 7, in <module>
    from tasks.parse_hh import get_dataset_with_tags
  File "/opt/airflow/dags/tasks/parse_hh.py", line 3, in <module>
    import fake_useragent
ModuleNotFoundError: No module named 'fake_useragent'
[2024-06-13T00:09:58.508+0000] {processor.py:841} WARNING - No viable dags retrieved from /opt/airflow/dags/data_etl_dag.py
[2024-06-13T00:09:58.520+0000] {processor.py:179} INFO - Processing /opt/airflow/dags/data_etl_dag.py took 0.068 seconds
[2024-06-13T00:10:28.665+0000] {processor.py:157} INFO - Started process (PID=1228) to work on /opt/airflow/dags/data_etl_dag.py
[2024-06-13T00:10:28.666+0000] {processor.py:829} INFO - Processing file /opt/airflow/dags/data_etl_dag.py for tasks to queue
[2024-06-13T00:10:28.667+0000] {logging_mixin.py:151} INFO - [2024-06-13T00:10:28.667+0000] {dagbag.py:536} INFO - Filling up the DagBag from /opt/airflow/dags/data_etl_dag.py
[2024-06-13T00:10:28.696+0000] {logging_mixin.py:151} INFO - [2024-06-13T00:10:28.693+0000] {dagbag.py:346} ERROR - Failed to import: /opt/airflow/dags/data_etl_dag.py
Traceback (most recent call last):
  File "/home/airflow/.local/lib/python3.8/site-packages/airflow/models/dagbag.py", line 342, in parse
    loader.exec_module(new_module)
  File "<frozen importlib._bootstrap_external>", line 843, in exec_module
  File "<frozen importlib._bootstrap>", line 219, in _call_with_frames_removed
  File "/opt/airflow/dags/data_etl_dag.py", line 7, in <module>
    from tasks.parse_hh import get_dataset_with_tags
  File "/opt/airflow/dags/tasks/parse_hh.py", line 3, in <module>
    import fake_useragent
ModuleNotFoundError: No module named 'fake_useragent'
[2024-06-13T00:10:28.697+0000] {processor.py:841} WARNING - No viable dags retrieved from /opt/airflow/dags/data_etl_dag.py
[2024-06-13T00:10:28.710+0000] {processor.py:179} INFO - Processing /opt/airflow/dags/data_etl_dag.py took 0.046 seconds
[2024-06-13T00:10:58.812+0000] {processor.py:157} INFO - Started process (PID=1240) to work on /opt/airflow/dags/data_etl_dag.py
[2024-06-13T00:10:58.812+0000] {processor.py:829} INFO - Processing file /opt/airflow/dags/data_etl_dag.py for tasks to queue
[2024-06-13T00:10:58.813+0000] {logging_mixin.py:151} INFO - [2024-06-13T00:10:58.813+0000] {dagbag.py:536} INFO - Filling up the DagBag from /opt/airflow/dags/data_etl_dag.py
[2024-06-13T00:10:58.839+0000] {logging_mixin.py:151} INFO - [2024-06-13T00:10:58.836+0000] {dagbag.py:346} ERROR - Failed to import: /opt/airflow/dags/data_etl_dag.py
Traceback (most recent call last):
  File "/home/airflow/.local/lib/python3.8/site-packages/airflow/models/dagbag.py", line 342, in parse
    loader.exec_module(new_module)
  File "<frozen importlib._bootstrap_external>", line 843, in exec_module
  File "<frozen importlib._bootstrap>", line 219, in _call_with_frames_removed
  File "/opt/airflow/dags/data_etl_dag.py", line 7, in <module>
    from tasks.parse_hh import get_dataset_with_tags
  File "/opt/airflow/dags/tasks/parse_hh.py", line 3, in <module>
    import fake_useragent
ModuleNotFoundError: No module named 'fake_useragent'
[2024-06-13T00:10:58.839+0000] {processor.py:841} WARNING - No viable dags retrieved from /opt/airflow/dags/data_etl_dag.py
[2024-06-13T00:10:58.852+0000] {processor.py:179} INFO - Processing /opt/airflow/dags/data_etl_dag.py took 0.042 seconds
[2024-06-13T00:11:28.968+0000] {processor.py:157} INFO - Started process (PID=1252) to work on /opt/airflow/dags/data_etl_dag.py
[2024-06-13T00:11:28.968+0000] {processor.py:829} INFO - Processing file /opt/airflow/dags/data_etl_dag.py for tasks to queue
[2024-06-13T00:11:28.969+0000] {logging_mixin.py:151} INFO - [2024-06-13T00:11:28.969+0000] {dagbag.py:536} INFO - Filling up the DagBag from /opt/airflow/dags/data_etl_dag.py
[2024-06-13T00:11:28.996+0000] {logging_mixin.py:151} INFO - [2024-06-13T00:11:28.993+0000] {dagbag.py:346} ERROR - Failed to import: /opt/airflow/dags/data_etl_dag.py
Traceback (most recent call last):
  File "/home/airflow/.local/lib/python3.8/site-packages/airflow/models/dagbag.py", line 342, in parse
    loader.exec_module(new_module)
  File "<frozen importlib._bootstrap_external>", line 843, in exec_module
  File "<frozen importlib._bootstrap>", line 219, in _call_with_frames_removed
  File "/opt/airflow/dags/data_etl_dag.py", line 7, in <module>
    from tasks.parse_hh import get_dataset_with_tags
  File "/opt/airflow/dags/tasks/parse_hh.py", line 3, in <module>
    import fake_useragent
ModuleNotFoundError: No module named 'fake_useragent'
[2024-06-13T00:11:28.997+0000] {processor.py:841} WARNING - No viable dags retrieved from /opt/airflow/dags/data_etl_dag.py
[2024-06-13T00:11:29.009+0000] {processor.py:179} INFO - Processing /opt/airflow/dags/data_etl_dag.py took 0.043 seconds
[2024-06-13T00:11:59.408+0000] {processor.py:157} INFO - Started process (PID=1264) to work on /opt/airflow/dags/data_etl_dag.py
[2024-06-13T00:11:59.408+0000] {processor.py:829} INFO - Processing file /opt/airflow/dags/data_etl_dag.py for tasks to queue
[2024-06-13T00:11:59.409+0000] {logging_mixin.py:151} INFO - [2024-06-13T00:11:59.409+0000] {dagbag.py:536} INFO - Filling up the DagBag from /opt/airflow/dags/data_etl_dag.py
[2024-06-13T00:11:59.435+0000] {logging_mixin.py:151} INFO - [2024-06-13T00:11:59.432+0000] {dagbag.py:346} ERROR - Failed to import: /opt/airflow/dags/data_etl_dag.py
Traceback (most recent call last):
  File "/home/airflow/.local/lib/python3.8/site-packages/airflow/models/dagbag.py", line 342, in parse
    loader.exec_module(new_module)
  File "<frozen importlib._bootstrap_external>", line 843, in exec_module
  File "<frozen importlib._bootstrap>", line 219, in _call_with_frames_removed
  File "/opt/airflow/dags/data_etl_dag.py", line 7, in <module>
    from tasks.parse_hh import get_dataset_with_tags
  File "/opt/airflow/dags/tasks/parse_hh.py", line 3, in <module>
    import fake_useragent
ModuleNotFoundError: No module named 'fake_useragent'
[2024-06-13T00:11:59.436+0000] {processor.py:841} WARNING - No viable dags retrieved from /opt/airflow/dags/data_etl_dag.py
[2024-06-13T00:11:59.448+0000] {processor.py:179} INFO - Processing /opt/airflow/dags/data_etl_dag.py took 0.042 seconds
[2024-06-13T00:12:29.550+0000] {processor.py:157} INFO - Started process (PID=1276) to work on /opt/airflow/dags/data_etl_dag.py
[2024-06-13T00:12:29.550+0000] {processor.py:829} INFO - Processing file /opt/airflow/dags/data_etl_dag.py for tasks to queue
[2024-06-13T00:12:29.551+0000] {logging_mixin.py:151} INFO - [2024-06-13T00:12:29.551+0000] {dagbag.py:536} INFO - Filling up the DagBag from /opt/airflow/dags/data_etl_dag.py
[2024-06-13T00:12:29.587+0000] {logging_mixin.py:151} INFO - [2024-06-13T00:12:29.584+0000] {dagbag.py:346} ERROR - Failed to import: /opt/airflow/dags/data_etl_dag.py
Traceback (most recent call last):
  File "/home/airflow/.local/lib/python3.8/site-packages/airflow/models/dagbag.py", line 342, in parse
    loader.exec_module(new_module)
  File "<frozen importlib._bootstrap_external>", line 843, in exec_module
  File "<frozen importlib._bootstrap>", line 219, in _call_with_frames_removed
  File "/opt/airflow/dags/data_etl_dag.py", line 7, in <module>
    from tasks.parse_hh import get_dataset_with_tags
  File "/opt/airflow/dags/tasks/parse_hh.py", line 3, in <module>
    import fake_useragent
ModuleNotFoundError: No module named 'fake_useragent'
[2024-06-13T00:12:29.588+0000] {processor.py:841} WARNING - No viable dags retrieved from /opt/airflow/dags/data_etl_dag.py
[2024-06-13T00:12:29.602+0000] {processor.py:179} INFO - Processing /opt/airflow/dags/data_etl_dag.py took 0.054 seconds
[2024-06-13T00:12:59.676+0000] {processor.py:157} INFO - Started process (PID=1288) to work on /opt/airflow/dags/data_etl_dag.py
[2024-06-13T00:12:59.677+0000] {processor.py:829} INFO - Processing file /opt/airflow/dags/data_etl_dag.py for tasks to queue
[2024-06-13T00:12:59.677+0000] {logging_mixin.py:151} INFO - [2024-06-13T00:12:59.677+0000] {dagbag.py:536} INFO - Filling up the DagBag from /opt/airflow/dags/data_etl_dag.py
[2024-06-13T00:12:59.704+0000] {logging_mixin.py:151} INFO - [2024-06-13T00:12:59.701+0000] {dagbag.py:346} ERROR - Failed to import: /opt/airflow/dags/data_etl_dag.py
Traceback (most recent call last):
  File "/home/airflow/.local/lib/python3.8/site-packages/airflow/models/dagbag.py", line 342, in parse
    loader.exec_module(new_module)
  File "<frozen importlib._bootstrap_external>", line 843, in exec_module
  File "<frozen importlib._bootstrap>", line 219, in _call_with_frames_removed
  File "/opt/airflow/dags/data_etl_dag.py", line 7, in <module>
    from tasks.parse_hh import get_dataset_with_tags
  File "/opt/airflow/dags/tasks/parse_hh.py", line 3, in <module>
    import fake_useragent
ModuleNotFoundError: No module named 'fake_useragent'
[2024-06-13T00:12:59.705+0000] {processor.py:841} WARNING - No viable dags retrieved from /opt/airflow/dags/data_etl_dag.py
[2024-06-13T00:12:59.808+0000] {processor.py:179} INFO - Processing /opt/airflow/dags/data_etl_dag.py took 0.134 seconds
[2024-06-13T00:13:29.877+0000] {processor.py:157} INFO - Started process (PID=1300) to work on /opt/airflow/dags/data_etl_dag.py
[2024-06-13T00:13:29.877+0000] {processor.py:829} INFO - Processing file /opt/airflow/dags/data_etl_dag.py for tasks to queue
[2024-06-13T00:13:29.878+0000] {logging_mixin.py:151} INFO - [2024-06-13T00:13:29.878+0000] {dagbag.py:536} INFO - Filling up the DagBag from /opt/airflow/dags/data_etl_dag.py
[2024-06-13T00:13:29.917+0000] {logging_mixin.py:151} INFO - [2024-06-13T00:13:29.911+0000] {dagbag.py:346} ERROR - Failed to import: /opt/airflow/dags/data_etl_dag.py
Traceback (most recent call last):
  File "/home/airflow/.local/lib/python3.8/site-packages/airflow/models/dagbag.py", line 342, in parse
    loader.exec_module(new_module)
  File "<frozen importlib._bootstrap_external>", line 843, in exec_module
  File "<frozen importlib._bootstrap>", line 219, in _call_with_frames_removed
  File "/opt/airflow/dags/data_etl_dag.py", line 7, in <module>
    from tasks.parse_hh import get_dataset_with_tags
  File "/opt/airflow/dags/tasks/parse_hh.py", line 3, in <module>
    import fake_useragent
ModuleNotFoundError: No module named 'fake_useragent'
[2024-06-13T00:13:29.918+0000] {processor.py:841} WARNING - No viable dags retrieved from /opt/airflow/dags/data_etl_dag.py
[2024-06-13T00:13:29.930+0000] {processor.py:179} INFO - Processing /opt/airflow/dags/data_etl_dag.py took 0.056 seconds
[2024-06-13T00:14:00.043+0000] {processor.py:157} INFO - Started process (PID=1312) to work on /opt/airflow/dags/data_etl_dag.py
[2024-06-13T00:14:00.044+0000] {processor.py:829} INFO - Processing file /opt/airflow/dags/data_etl_dag.py for tasks to queue
[2024-06-13T00:14:00.044+0000] {logging_mixin.py:151} INFO - [2024-06-13T00:14:00.044+0000] {dagbag.py:536} INFO - Filling up the DagBag from /opt/airflow/dags/data_etl_dag.py
[2024-06-13T00:14:00.073+0000] {logging_mixin.py:151} INFO - [2024-06-13T00:14:00.070+0000] {dagbag.py:346} ERROR - Failed to import: /opt/airflow/dags/data_etl_dag.py
Traceback (most recent call last):
  File "/home/airflow/.local/lib/python3.8/site-packages/airflow/models/dagbag.py", line 342, in parse
    loader.exec_module(new_module)
  File "<frozen importlib._bootstrap_external>", line 843, in exec_module
  File "<frozen importlib._bootstrap>", line 219, in _call_with_frames_removed
  File "/opt/airflow/dags/data_etl_dag.py", line 7, in <module>
    from tasks.parse_hh import get_dataset_with_tags
  File "/opt/airflow/dags/tasks/parse_hh.py", line 3, in <module>
    import fake_useragent
ModuleNotFoundError: No module named 'fake_useragent'
[2024-06-13T00:14:00.074+0000] {processor.py:841} WARNING - No viable dags retrieved from /opt/airflow/dags/data_etl_dag.py
[2024-06-13T00:14:00.087+0000] {processor.py:179} INFO - Processing /opt/airflow/dags/data_etl_dag.py took 0.046 seconds
[2024-06-13T00:14:30.181+0000] {processor.py:157} INFO - Started process (PID=1324) to work on /opt/airflow/dags/data_etl_dag.py
[2024-06-13T00:14:30.182+0000] {processor.py:829} INFO - Processing file /opt/airflow/dags/data_etl_dag.py for tasks to queue
[2024-06-13T00:14:30.183+0000] {logging_mixin.py:151} INFO - [2024-06-13T00:14:30.183+0000] {dagbag.py:536} INFO - Filling up the DagBag from /opt/airflow/dags/data_etl_dag.py
[2024-06-13T00:14:30.221+0000] {logging_mixin.py:151} INFO - [2024-06-13T00:14:30.217+0000] {dagbag.py:346} ERROR - Failed to import: /opt/airflow/dags/data_etl_dag.py
Traceback (most recent call last):
  File "/home/airflow/.local/lib/python3.8/site-packages/airflow/models/dagbag.py", line 342, in parse
    loader.exec_module(new_module)
  File "<frozen importlib._bootstrap_external>", line 843, in exec_module
  File "<frozen importlib._bootstrap>", line 219, in _call_with_frames_removed
  File "/opt/airflow/dags/data_etl_dag.py", line 7, in <module>
    from tasks.parse_hh import get_dataset_with_tags
  File "/opt/airflow/dags/tasks/parse_hh.py", line 3, in <module>
    import fake_useragent
ModuleNotFoundError: No module named 'fake_useragent'
[2024-06-13T00:14:30.222+0000] {processor.py:841} WARNING - No viable dags retrieved from /opt/airflow/dags/data_etl_dag.py
[2024-06-13T00:14:30.234+0000] {processor.py:179} INFO - Processing /opt/airflow/dags/data_etl_dag.py took 0.055 seconds
[2024-06-13T00:15:00.332+0000] {processor.py:157} INFO - Started process (PID=1335) to work on /opt/airflow/dags/data_etl_dag.py
[2024-06-13T00:15:00.333+0000] {processor.py:829} INFO - Processing file /opt/airflow/dags/data_etl_dag.py for tasks to queue
[2024-06-13T00:15:00.334+0000] {logging_mixin.py:151} INFO - [2024-06-13T00:15:00.333+0000] {dagbag.py:536} INFO - Filling up the DagBag from /opt/airflow/dags/data_etl_dag.py
[2024-06-13T00:15:00.367+0000] {logging_mixin.py:151} INFO - [2024-06-13T00:15:00.363+0000] {dagbag.py:346} ERROR - Failed to import: /opt/airflow/dags/data_etl_dag.py
Traceback (most recent call last):
  File "/home/airflow/.local/lib/python3.8/site-packages/airflow/models/dagbag.py", line 342, in parse
    loader.exec_module(new_module)
  File "<frozen importlib._bootstrap_external>", line 843, in exec_module
  File "<frozen importlib._bootstrap>", line 219, in _call_with_frames_removed
  File "/opt/airflow/dags/data_etl_dag.py", line 7, in <module>
    from tasks.parse_hh import get_dataset_with_tags
  File "/opt/airflow/dags/tasks/parse_hh.py", line 3, in <module>
    import fake_useragent
ModuleNotFoundError: No module named 'fake_useragent'
[2024-06-13T00:15:00.368+0000] {processor.py:841} WARNING - No viable dags retrieved from /opt/airflow/dags/data_etl_dag.py
[2024-06-13T00:15:00.383+0000] {processor.py:179} INFO - Processing /opt/airflow/dags/data_etl_dag.py took 0.053 seconds
[2024-06-13T00:15:30.484+0000] {processor.py:157} INFO - Started process (PID=1346) to work on /opt/airflow/dags/data_etl_dag.py
[2024-06-13T00:15:30.485+0000] {processor.py:829} INFO - Processing file /opt/airflow/dags/data_etl_dag.py for tasks to queue
[2024-06-13T00:15:30.485+0000] {logging_mixin.py:151} INFO - [2024-06-13T00:15:30.485+0000] {dagbag.py:536} INFO - Filling up the DagBag from /opt/airflow/dags/data_etl_dag.py
[2024-06-13T00:15:30.536+0000] {logging_mixin.py:151} INFO - [2024-06-13T00:15:30.528+0000] {dagbag.py:346} ERROR - Failed to import: /opt/airflow/dags/data_etl_dag.py
Traceback (most recent call last):
  File "/home/airflow/.local/lib/python3.8/site-packages/airflow/models/dagbag.py", line 342, in parse
    loader.exec_module(new_module)
  File "<frozen importlib._bootstrap_external>", line 843, in exec_module
  File "<frozen importlib._bootstrap>", line 219, in _call_with_frames_removed
  File "/opt/airflow/dags/data_etl_dag.py", line 7, in <module>
    from tasks.parse_hh import get_dataset_with_tags
  File "/opt/airflow/dags/tasks/parse_hh.py", line 3, in <module>
    import fake_useragent
ModuleNotFoundError: No module named 'fake_useragent'
[2024-06-13T00:15:30.537+0000] {processor.py:841} WARNING - No viable dags retrieved from /opt/airflow/dags/data_etl_dag.py
[2024-06-13T00:15:30.550+0000] {processor.py:179} INFO - Processing /opt/airflow/dags/data_etl_dag.py took 0.068 seconds
[2024-06-13T00:16:00.674+0000] {processor.py:157} INFO - Started process (PID=1358) to work on /opt/airflow/dags/data_etl_dag.py
[2024-06-13T00:16:00.674+0000] {processor.py:829} INFO - Processing file /opt/airflow/dags/data_etl_dag.py for tasks to queue
[2024-06-13T00:16:00.675+0000] {logging_mixin.py:151} INFO - [2024-06-13T00:16:00.675+0000] {dagbag.py:536} INFO - Filling up the DagBag from /opt/airflow/dags/data_etl_dag.py
[2024-06-13T00:16:00.714+0000] {logging_mixin.py:151} INFO - [2024-06-13T00:16:00.707+0000] {dagbag.py:346} ERROR - Failed to import: /opt/airflow/dags/data_etl_dag.py
Traceback (most recent call last):
  File "/home/airflow/.local/lib/python3.8/site-packages/airflow/models/dagbag.py", line 342, in parse
    loader.exec_module(new_module)
  File "<frozen importlib._bootstrap_external>", line 843, in exec_module
  File "<frozen importlib._bootstrap>", line 219, in _call_with_frames_removed
  File "/opt/airflow/dags/data_etl_dag.py", line 7, in <module>
    from tasks.parse_hh import get_dataset_with_tags
  File "/opt/airflow/dags/tasks/parse_hh.py", line 3, in <module>
    import fake_useragent
ModuleNotFoundError: No module named 'fake_useragent'
[2024-06-13T00:16:00.716+0000] {processor.py:841} WARNING - No viable dags retrieved from /opt/airflow/dags/data_etl_dag.py
[2024-06-13T00:16:00.728+0000] {processor.py:179} INFO - Processing /opt/airflow/dags/data_etl_dag.py took 0.056 seconds
[2024-06-13T00:16:30.801+0000] {processor.py:157} INFO - Started process (PID=1370) to work on /opt/airflow/dags/data_etl_dag.py
[2024-06-13T00:16:30.802+0000] {processor.py:829} INFO - Processing file /opt/airflow/dags/data_etl_dag.py for tasks to queue
[2024-06-13T00:16:30.802+0000] {logging_mixin.py:151} INFO - [2024-06-13T00:16:30.802+0000] {dagbag.py:536} INFO - Filling up the DagBag from /opt/airflow/dags/data_etl_dag.py
[2024-06-13T00:16:30.837+0000] {logging_mixin.py:151} INFO - [2024-06-13T00:16:30.829+0000] {dagbag.py:346} ERROR - Failed to import: /opt/airflow/dags/data_etl_dag.py
Traceback (most recent call last):
  File "/home/airflow/.local/lib/python3.8/site-packages/airflow/models/dagbag.py", line 342, in parse
    loader.exec_module(new_module)
  File "<frozen importlib._bootstrap_external>", line 843, in exec_module
  File "<frozen importlib._bootstrap>", line 219, in _call_with_frames_removed
  File "/opt/airflow/dags/data_etl_dag.py", line 7, in <module>
    from tasks.parse_hh import get_dataset_with_tags
  File "/opt/airflow/dags/tasks/parse_hh.py", line 3, in <module>
    import fake_useragent
ModuleNotFoundError: No module named 'fake_useragent'
[2024-06-13T00:16:30.838+0000] {processor.py:841} WARNING - No viable dags retrieved from /opt/airflow/dags/data_etl_dag.py
[2024-06-13T00:16:30.852+0000] {processor.py:179} INFO - Processing /opt/airflow/dags/data_etl_dag.py took 0.053 seconds
[2024-06-13T00:17:01.233+0000] {processor.py:157} INFO - Started process (PID=1382) to work on /opt/airflow/dags/data_etl_dag.py
[2024-06-13T00:17:01.233+0000] {processor.py:829} INFO - Processing file /opt/airflow/dags/data_etl_dag.py for tasks to queue
[2024-06-13T00:17:01.234+0000] {logging_mixin.py:151} INFO - [2024-06-13T00:17:01.234+0000] {dagbag.py:536} INFO - Filling up the DagBag from /opt/airflow/dags/data_etl_dag.py
[2024-06-13T00:17:01.263+0000] {logging_mixin.py:151} INFO - [2024-06-13T00:17:01.260+0000] {dagbag.py:346} ERROR - Failed to import: /opt/airflow/dags/data_etl_dag.py
Traceback (most recent call last):
  File "/home/airflow/.local/lib/python3.8/site-packages/airflow/models/dagbag.py", line 342, in parse
    loader.exec_module(new_module)
  File "<frozen importlib._bootstrap_external>", line 843, in exec_module
  File "<frozen importlib._bootstrap>", line 219, in _call_with_frames_removed
  File "/opt/airflow/dags/data_etl_dag.py", line 7, in <module>
    from tasks.parse_hh import get_dataset_with_tags
  File "/opt/airflow/dags/tasks/parse_hh.py", line 3, in <module>
    import fake_useragent
ModuleNotFoundError: No module named 'fake_useragent'
[2024-06-13T00:17:01.264+0000] {processor.py:841} WARNING - No viable dags retrieved from /opt/airflow/dags/data_etl_dag.py
[2024-06-13T00:17:01.277+0000] {processor.py:179} INFO - Processing /opt/airflow/dags/data_etl_dag.py took 0.047 seconds
[2024-06-13T00:17:31.362+0000] {processor.py:157} INFO - Started process (PID=1394) to work on /opt/airflow/dags/data_etl_dag.py
[2024-06-13T00:17:31.363+0000] {processor.py:829} INFO - Processing file /opt/airflow/dags/data_etl_dag.py for tasks to queue
[2024-06-13T00:17:31.363+0000] {logging_mixin.py:151} INFO - [2024-06-13T00:17:31.363+0000] {dagbag.py:536} INFO - Filling up the DagBag from /opt/airflow/dags/data_etl_dag.py
[2024-06-13T00:17:31.394+0000] {logging_mixin.py:151} INFO - [2024-06-13T00:17:31.391+0000] {dagbag.py:346} ERROR - Failed to import: /opt/airflow/dags/data_etl_dag.py
Traceback (most recent call last):
  File "/home/airflow/.local/lib/python3.8/site-packages/airflow/models/dagbag.py", line 342, in parse
    loader.exec_module(new_module)
  File "<frozen importlib._bootstrap_external>", line 843, in exec_module
  File "<frozen importlib._bootstrap>", line 219, in _call_with_frames_removed
  File "/opt/airflow/dags/data_etl_dag.py", line 7, in <module>
    from tasks.parse_hh import get_dataset_with_tags
  File "/opt/airflow/dags/tasks/parse_hh.py", line 3, in <module>
    import fake_useragent
ModuleNotFoundError: No module named 'fake_useragent'
[2024-06-13T00:17:31.395+0000] {processor.py:841} WARNING - No viable dags retrieved from /opt/airflow/dags/data_etl_dag.py
[2024-06-13T00:17:31.409+0000] {processor.py:179} INFO - Processing /opt/airflow/dags/data_etl_dag.py took 0.049 seconds
[2024-06-13T00:18:01.525+0000] {processor.py:157} INFO - Started process (PID=1406) to work on /opt/airflow/dags/data_etl_dag.py
[2024-06-13T00:18:01.525+0000] {processor.py:829} INFO - Processing file /opt/airflow/dags/data_etl_dag.py for tasks to queue
[2024-06-13T00:18:01.526+0000] {logging_mixin.py:151} INFO - [2024-06-13T00:18:01.526+0000] {dagbag.py:536} INFO - Filling up the DagBag from /opt/airflow/dags/data_etl_dag.py
[2024-06-13T00:18:01.565+0000] {logging_mixin.py:151} INFO - [2024-06-13T00:18:01.559+0000] {dagbag.py:346} ERROR - Failed to import: /opt/airflow/dags/data_etl_dag.py
Traceback (most recent call last):
  File "/home/airflow/.local/lib/python3.8/site-packages/airflow/models/dagbag.py", line 342, in parse
    loader.exec_module(new_module)
  File "<frozen importlib._bootstrap_external>", line 843, in exec_module
  File "<frozen importlib._bootstrap>", line 219, in _call_with_frames_removed
  File "/opt/airflow/dags/data_etl_dag.py", line 7, in <module>
    from tasks.parse_hh import get_dataset_with_tags
  File "/opt/airflow/dags/tasks/parse_hh.py", line 3, in <module>
    import fake_useragent
ModuleNotFoundError: No module named 'fake_useragent'
[2024-06-13T00:18:01.567+0000] {processor.py:841} WARNING - No viable dags retrieved from /opt/airflow/dags/data_etl_dag.py
[2024-06-13T00:18:01.584+0000] {processor.py:179} INFO - Processing /opt/airflow/dags/data_etl_dag.py took 0.062 seconds
[2024-06-13T00:18:31.662+0000] {processor.py:157} INFO - Started process (PID=1418) to work on /opt/airflow/dags/data_etl_dag.py
[2024-06-13T00:18:31.663+0000] {processor.py:829} INFO - Processing file /opt/airflow/dags/data_etl_dag.py for tasks to queue
[2024-06-13T00:18:31.663+0000] {logging_mixin.py:151} INFO - [2024-06-13T00:18:31.663+0000] {dagbag.py:536} INFO - Filling up the DagBag from /opt/airflow/dags/data_etl_dag.py
[2024-06-13T00:18:31.696+0000] {logging_mixin.py:151} INFO - [2024-06-13T00:18:31.693+0000] {dagbag.py:346} ERROR - Failed to import: /opt/airflow/dags/data_etl_dag.py
Traceback (most recent call last):
  File "/home/airflow/.local/lib/python3.8/site-packages/airflow/models/dagbag.py", line 342, in parse
    loader.exec_module(new_module)
  File "<frozen importlib._bootstrap_external>", line 843, in exec_module
  File "<frozen importlib._bootstrap>", line 219, in _call_with_frames_removed
  File "/opt/airflow/dags/data_etl_dag.py", line 7, in <module>
    from tasks.parse_hh import get_dataset_with_tags
  File "/opt/airflow/dags/tasks/parse_hh.py", line 3, in <module>
    import fake_useragent
ModuleNotFoundError: No module named 'fake_useragent'
[2024-06-13T00:18:31.697+0000] {processor.py:841} WARNING - No viable dags retrieved from /opt/airflow/dags/data_etl_dag.py
[2024-06-13T00:18:31.712+0000] {processor.py:179} INFO - Processing /opt/airflow/dags/data_etl_dag.py took 0.052 seconds
[2024-06-13T00:19:01.796+0000] {processor.py:157} INFO - Started process (PID=1430) to work on /opt/airflow/dags/data_etl_dag.py
[2024-06-13T00:19:01.796+0000] {processor.py:829} INFO - Processing file /opt/airflow/dags/data_etl_dag.py for tasks to queue
[2024-06-13T00:19:01.797+0000] {logging_mixin.py:151} INFO - [2024-06-13T00:19:01.797+0000] {dagbag.py:536} INFO - Filling up the DagBag from /opt/airflow/dags/data_etl_dag.py
[2024-06-13T00:19:01.827+0000] {logging_mixin.py:151} INFO - [2024-06-13T00:19:01.824+0000] {dagbag.py:346} ERROR - Failed to import: /opt/airflow/dags/data_etl_dag.py
Traceback (most recent call last):
  File "/home/airflow/.local/lib/python3.8/site-packages/airflow/models/dagbag.py", line 342, in parse
    loader.exec_module(new_module)
  File "<frozen importlib._bootstrap_external>", line 843, in exec_module
  File "<frozen importlib._bootstrap>", line 219, in _call_with_frames_removed
  File "/opt/airflow/dags/data_etl_dag.py", line 7, in <module>
    from tasks.parse_hh import get_dataset_with_tags
  File "/opt/airflow/dags/tasks/parse_hh.py", line 3, in <module>
    import fake_useragent
ModuleNotFoundError: No module named 'fake_useragent'
[2024-06-13T00:19:01.828+0000] {processor.py:841} WARNING - No viable dags retrieved from /opt/airflow/dags/data_etl_dag.py
[2024-06-13T00:19:01.842+0000] {processor.py:179} INFO - Processing /opt/airflow/dags/data_etl_dag.py took 0.048 seconds
[2024-06-13T00:19:32.008+0000] {processor.py:157} INFO - Started process (PID=1441) to work on /opt/airflow/dags/data_etl_dag.py
[2024-06-13T00:19:32.009+0000] {processor.py:829} INFO - Processing file /opt/airflow/dags/data_etl_dag.py for tasks to queue
[2024-06-13T00:19:32.009+0000] {logging_mixin.py:151} INFO - [2024-06-13T00:19:32.009+0000] {dagbag.py:536} INFO - Filling up the DagBag from /opt/airflow/dags/data_etl_dag.py
[2024-06-13T00:19:32.036+0000] {logging_mixin.py:151} INFO - [2024-06-13T00:19:32.034+0000] {dagbag.py:346} ERROR - Failed to import: /opt/airflow/dags/data_etl_dag.py
Traceback (most recent call last):
  File "/home/airflow/.local/lib/python3.8/site-packages/airflow/models/dagbag.py", line 342, in parse
    loader.exec_module(new_module)
  File "<frozen importlib._bootstrap_external>", line 843, in exec_module
  File "<frozen importlib._bootstrap>", line 219, in _call_with_frames_removed
  File "/opt/airflow/dags/data_etl_dag.py", line 7, in <module>
    from tasks.parse_hh import get_dataset_with_tags
  File "/opt/airflow/dags/tasks/parse_hh.py", line 3, in <module>
    import fake_useragent
ModuleNotFoundError: No module named 'fake_useragent'
[2024-06-13T00:19:32.037+0000] {processor.py:841} WARNING - No viable dags retrieved from /opt/airflow/dags/data_etl_dag.py
[2024-06-13T00:19:32.050+0000] {processor.py:179} INFO - Processing /opt/airflow/dags/data_etl_dag.py took 0.043 seconds
[2024-06-13T00:20:02.169+0000] {processor.py:157} INFO - Started process (PID=1453) to work on /opt/airflow/dags/data_etl_dag.py
[2024-06-13T00:20:02.170+0000] {processor.py:829} INFO - Processing file /opt/airflow/dags/data_etl_dag.py for tasks to queue
[2024-06-13T00:20:02.170+0000] {logging_mixin.py:151} INFO - [2024-06-13T00:20:02.170+0000] {dagbag.py:536} INFO - Filling up the DagBag from /opt/airflow/dags/data_etl_dag.py
[2024-06-13T00:20:02.202+0000] {logging_mixin.py:151} INFO - [2024-06-13T00:20:02.199+0000] {dagbag.py:346} ERROR - Failed to import: /opt/airflow/dags/data_etl_dag.py
Traceback (most recent call last):
  File "/home/airflow/.local/lib/python3.8/site-packages/airflow/models/dagbag.py", line 342, in parse
    loader.exec_module(new_module)
  File "<frozen importlib._bootstrap_external>", line 843, in exec_module
  File "<frozen importlib._bootstrap>", line 219, in _call_with_frames_removed
  File "/opt/airflow/dags/data_etl_dag.py", line 7, in <module>
    from tasks.parse_hh import get_dataset_with_tags
  File "/opt/airflow/dags/tasks/parse_hh.py", line 3, in <module>
    import fake_useragent
ModuleNotFoundError: No module named 'fake_useragent'
[2024-06-13T00:20:02.203+0000] {processor.py:841} WARNING - No viable dags retrieved from /opt/airflow/dags/data_etl_dag.py
[2024-06-13T00:20:02.215+0000] {processor.py:179} INFO - Processing /opt/airflow/dags/data_etl_dag.py took 0.048 seconds
[2024-06-13T00:20:32.327+0000] {processor.py:157} INFO - Started process (PID=1465) to work on /opt/airflow/dags/data_etl_dag.py
[2024-06-13T00:20:32.327+0000] {processor.py:829} INFO - Processing file /opt/airflow/dags/data_etl_dag.py for tasks to queue
[2024-06-13T00:20:32.329+0000] {logging_mixin.py:151} INFO - [2024-06-13T00:20:32.329+0000] {dagbag.py:536} INFO - Filling up the DagBag from /opt/airflow/dags/data_etl_dag.py
[2024-06-13T00:20:32.368+0000] {logging_mixin.py:151} INFO - [2024-06-13T00:20:32.364+0000] {dagbag.py:346} ERROR - Failed to import: /opt/airflow/dags/data_etl_dag.py
Traceback (most recent call last):
  File "/home/airflow/.local/lib/python3.8/site-packages/airflow/models/dagbag.py", line 342, in parse
    loader.exec_module(new_module)
  File "<frozen importlib._bootstrap_external>", line 843, in exec_module
  File "<frozen importlib._bootstrap>", line 219, in _call_with_frames_removed
  File "/opt/airflow/dags/data_etl_dag.py", line 7, in <module>
    from tasks.parse_hh import get_dataset_with_tags
  File "/opt/airflow/dags/tasks/parse_hh.py", line 3, in <module>
    import fake_useragent
ModuleNotFoundError: No module named 'fake_useragent'
[2024-06-13T00:20:32.369+0000] {processor.py:841} WARNING - No viable dags retrieved from /opt/airflow/dags/data_etl_dag.py
[2024-06-13T00:20:32.382+0000] {processor.py:179} INFO - Processing /opt/airflow/dags/data_etl_dag.py took 0.057 seconds
[2024-06-13T00:21:02.486+0000] {processor.py:157} INFO - Started process (PID=1477) to work on /opt/airflow/dags/data_etl_dag.py
[2024-06-13T00:21:02.487+0000] {processor.py:829} INFO - Processing file /opt/airflow/dags/data_etl_dag.py for tasks to queue
[2024-06-13T00:21:02.487+0000] {logging_mixin.py:151} INFO - [2024-06-13T00:21:02.487+0000] {dagbag.py:536} INFO - Filling up the DagBag from /opt/airflow/dags/data_etl_dag.py
[2024-06-13T00:21:02.532+0000] {logging_mixin.py:151} INFO - [2024-06-13T00:21:02.528+0000] {dagbag.py:346} ERROR - Failed to import: /opt/airflow/dags/data_etl_dag.py
Traceback (most recent call last):
  File "/home/airflow/.local/lib/python3.8/site-packages/airflow/models/dagbag.py", line 342, in parse
    loader.exec_module(new_module)
  File "<frozen importlib._bootstrap_external>", line 843, in exec_module
  File "<frozen importlib._bootstrap>", line 219, in _call_with_frames_removed
  File "/opt/airflow/dags/data_etl_dag.py", line 7, in <module>
    from tasks.parse_hh import get_dataset_with_tags
  File "/opt/airflow/dags/tasks/parse_hh.py", line 3, in <module>
    import fake_useragent
ModuleNotFoundError: No module named 'fake_useragent'
[2024-06-13T00:21:02.534+0000] {processor.py:841} WARNING - No viable dags retrieved from /opt/airflow/dags/data_etl_dag.py
[2024-06-13T00:21:02.546+0000] {processor.py:179} INFO - Processing /opt/airflow/dags/data_etl_dag.py took 0.063 seconds
[2024-06-13T00:21:32.656+0000] {processor.py:157} INFO - Started process (PID=1489) to work on /opt/airflow/dags/data_etl_dag.py
[2024-06-13T00:21:32.657+0000] {processor.py:829} INFO - Processing file /opt/airflow/dags/data_etl_dag.py for tasks to queue
[2024-06-13T00:21:32.657+0000] {logging_mixin.py:151} INFO - [2024-06-13T00:21:32.657+0000] {dagbag.py:536} INFO - Filling up the DagBag from /opt/airflow/dags/data_etl_dag.py
[2024-06-13T00:21:32.692+0000] {logging_mixin.py:151} INFO - [2024-06-13T00:21:32.688+0000] {dagbag.py:346} ERROR - Failed to import: /opt/airflow/dags/data_etl_dag.py
Traceback (most recent call last):
  File "/home/airflow/.local/lib/python3.8/site-packages/airflow/models/dagbag.py", line 342, in parse
    loader.exec_module(new_module)
  File "<frozen importlib._bootstrap_external>", line 843, in exec_module
  File "<frozen importlib._bootstrap>", line 219, in _call_with_frames_removed
  File "/opt/airflow/dags/data_etl_dag.py", line 7, in <module>
    from tasks.parse_hh import get_dataset_with_tags
  File "/opt/airflow/dags/tasks/parse_hh.py", line 3, in <module>
    import fake_useragent
ModuleNotFoundError: No module named 'fake_useragent'
[2024-06-13T00:21:32.693+0000] {processor.py:841} WARNING - No viable dags retrieved from /opt/airflow/dags/data_etl_dag.py
[2024-06-13T00:21:32.707+0000] {processor.py:179} INFO - Processing /opt/airflow/dags/data_etl_dag.py took 0.052 seconds
[2024-06-13T00:22:03.119+0000] {processor.py:157} INFO - Started process (PID=1501) to work on /opt/airflow/dags/data_etl_dag.py
[2024-06-13T00:22:03.119+0000] {processor.py:829} INFO - Processing file /opt/airflow/dags/data_etl_dag.py for tasks to queue
[2024-06-13T00:22:03.120+0000] {logging_mixin.py:151} INFO - [2024-06-13T00:22:03.120+0000] {dagbag.py:536} INFO - Filling up the DagBag from /opt/airflow/dags/data_etl_dag.py
[2024-06-13T00:22:03.149+0000] {logging_mixin.py:151} INFO - [2024-06-13T00:22:03.146+0000] {dagbag.py:346} ERROR - Failed to import: /opt/airflow/dags/data_etl_dag.py
Traceback (most recent call last):
  File "/home/airflow/.local/lib/python3.8/site-packages/airflow/models/dagbag.py", line 342, in parse
    loader.exec_module(new_module)
  File "<frozen importlib._bootstrap_external>", line 843, in exec_module
  File "<frozen importlib._bootstrap>", line 219, in _call_with_frames_removed
  File "/opt/airflow/dags/data_etl_dag.py", line 7, in <module>
    from tasks.parse_hh import get_dataset_with_tags
  File "/opt/airflow/dags/tasks/parse_hh.py", line 3, in <module>
    import fake_useragent
ModuleNotFoundError: No module named 'fake_useragent'
[2024-06-13T00:22:03.150+0000] {processor.py:841} WARNING - No viable dags retrieved from /opt/airflow/dags/data_etl_dag.py
[2024-06-13T00:22:03.161+0000] {processor.py:179} INFO - Processing /opt/airflow/dags/data_etl_dag.py took 0.045 seconds
[2024-06-13T00:22:33.253+0000] {processor.py:157} INFO - Started process (PID=1513) to work on /opt/airflow/dags/data_etl_dag.py
[2024-06-13T00:22:33.254+0000] {processor.py:829} INFO - Processing file /opt/airflow/dags/data_etl_dag.py for tasks to queue
[2024-06-13T00:22:33.255+0000] {logging_mixin.py:151} INFO - [2024-06-13T00:22:33.254+0000] {dagbag.py:536} INFO - Filling up the DagBag from /opt/airflow/dags/data_etl_dag.py
[2024-06-13T00:22:33.287+0000] {logging_mixin.py:151} INFO - [2024-06-13T00:22:33.284+0000] {dagbag.py:346} ERROR - Failed to import: /opt/airflow/dags/data_etl_dag.py
Traceback (most recent call last):
  File "/home/airflow/.local/lib/python3.8/site-packages/airflow/models/dagbag.py", line 342, in parse
    loader.exec_module(new_module)
  File "<frozen importlib._bootstrap_external>", line 843, in exec_module
  File "<frozen importlib._bootstrap>", line 219, in _call_with_frames_removed
  File "/opt/airflow/dags/data_etl_dag.py", line 7, in <module>
    from tasks.parse_hh import get_dataset_with_tags
  File "/opt/airflow/dags/tasks/parse_hh.py", line 3, in <module>
    import fake_useragent
ModuleNotFoundError: No module named 'fake_useragent'
[2024-06-13T00:22:33.289+0000] {processor.py:841} WARNING - No viable dags retrieved from /opt/airflow/dags/data_etl_dag.py
[2024-06-13T00:22:33.300+0000] {processor.py:179} INFO - Processing /opt/airflow/dags/data_etl_dag.py took 0.049 seconds
[2024-06-13T00:23:03.422+0000] {processor.py:157} INFO - Started process (PID=1525) to work on /opt/airflow/dags/data_etl_dag.py
[2024-06-13T00:23:03.423+0000] {processor.py:829} INFO - Processing file /opt/airflow/dags/data_etl_dag.py for tasks to queue
[2024-06-13T00:23:03.424+0000] {logging_mixin.py:151} INFO - [2024-06-13T00:23:03.423+0000] {dagbag.py:536} INFO - Filling up the DagBag from /opt/airflow/dags/data_etl_dag.py
[2024-06-13T00:23:03.455+0000] {logging_mixin.py:151} INFO - [2024-06-13T00:23:03.451+0000] {dagbag.py:346} ERROR - Failed to import: /opt/airflow/dags/data_etl_dag.py
Traceback (most recent call last):
  File "/home/airflow/.local/lib/python3.8/site-packages/airflow/models/dagbag.py", line 342, in parse
    loader.exec_module(new_module)
  File "<frozen importlib._bootstrap_external>", line 843, in exec_module
  File "<frozen importlib._bootstrap>", line 219, in _call_with_frames_removed
  File "/opt/airflow/dags/data_etl_dag.py", line 7, in <module>
    from tasks.parse_hh import get_dataset_with_tags
  File "/opt/airflow/dags/tasks/parse_hh.py", line 3, in <module>
    import fake_useragent
ModuleNotFoundError: No module named 'fake_useragent'
[2024-06-13T00:23:03.456+0000] {processor.py:841} WARNING - No viable dags retrieved from /opt/airflow/dags/data_etl_dag.py
[2024-06-13T00:23:03.470+0000] {processor.py:179} INFO - Processing /opt/airflow/dags/data_etl_dag.py took 0.050 seconds
[2024-06-13T00:23:33.562+0000] {processor.py:157} INFO - Started process (PID=1537) to work on /opt/airflow/dags/data_etl_dag.py
[2024-06-13T00:23:33.562+0000] {processor.py:829} INFO - Processing file /opt/airflow/dags/data_etl_dag.py for tasks to queue
[2024-06-13T00:23:33.563+0000] {logging_mixin.py:151} INFO - [2024-06-13T00:23:33.563+0000] {dagbag.py:536} INFO - Filling up the DagBag from /opt/airflow/dags/data_etl_dag.py
[2024-06-13T00:23:33.591+0000] {logging_mixin.py:151} INFO - [2024-06-13T00:23:33.588+0000] {dagbag.py:346} ERROR - Failed to import: /opt/airflow/dags/data_etl_dag.py
Traceback (most recent call last):
  File "/home/airflow/.local/lib/python3.8/site-packages/airflow/models/dagbag.py", line 342, in parse
    loader.exec_module(new_module)
  File "<frozen importlib._bootstrap_external>", line 843, in exec_module
  File "<frozen importlib._bootstrap>", line 219, in _call_with_frames_removed
  File "/opt/airflow/dags/data_etl_dag.py", line 7, in <module>
    from tasks.parse_hh import get_dataset_with_tags
  File "/opt/airflow/dags/tasks/parse_hh.py", line 3, in <module>
    import fake_useragent
ModuleNotFoundError: No module named 'fake_useragent'
[2024-06-13T00:23:33.592+0000] {processor.py:841} WARNING - No viable dags retrieved from /opt/airflow/dags/data_etl_dag.py
[2024-06-13T00:23:33.605+0000] {processor.py:179} INFO - Processing /opt/airflow/dags/data_etl_dag.py took 0.046 seconds
[2024-06-13T00:24:03.752+0000] {processor.py:157} INFO - Started process (PID=1549) to work on /opt/airflow/dags/data_etl_dag.py
[2024-06-13T00:24:03.753+0000] {processor.py:829} INFO - Processing file /opt/airflow/dags/data_etl_dag.py for tasks to queue
[2024-06-13T00:24:03.753+0000] {logging_mixin.py:151} INFO - [2024-06-13T00:24:03.753+0000] {dagbag.py:536} INFO - Filling up the DagBag from /opt/airflow/dags/data_etl_dag.py
[2024-06-13T00:24:03.801+0000] {logging_mixin.py:151} INFO - [2024-06-13T00:24:03.796+0000] {dagbag.py:346} ERROR - Failed to import: /opt/airflow/dags/data_etl_dag.py
Traceback (most recent call last):
  File "/home/airflow/.local/lib/python3.8/site-packages/airflow/models/dagbag.py", line 342, in parse
    loader.exec_module(new_module)
  File "<frozen importlib._bootstrap_external>", line 843, in exec_module
  File "<frozen importlib._bootstrap>", line 219, in _call_with_frames_removed
  File "/opt/airflow/dags/data_etl_dag.py", line 7, in <module>
    from tasks.parse_hh import get_dataset_with_tags
  File "/opt/airflow/dags/tasks/parse_hh.py", line 3, in <module>
    import fake_useragent
ModuleNotFoundError: No module named 'fake_useragent'
[2024-06-13T00:24:03.802+0000] {processor.py:841} WARNING - No viable dags retrieved from /opt/airflow/dags/data_etl_dag.py
[2024-06-13T00:24:03.815+0000] {processor.py:179} INFO - Processing /opt/airflow/dags/data_etl_dag.py took 0.065 seconds
[2024-06-13T00:24:33.897+0000] {processor.py:157} INFO - Started process (PID=1561) to work on /opt/airflow/dags/data_etl_dag.py
[2024-06-13T00:24:33.897+0000] {processor.py:829} INFO - Processing file /opt/airflow/dags/data_etl_dag.py for tasks to queue
[2024-06-13T00:24:33.898+0000] {logging_mixin.py:151} INFO - [2024-06-13T00:24:33.898+0000] {dagbag.py:536} INFO - Filling up the DagBag from /opt/airflow/dags/data_etl_dag.py
[2024-06-13T00:24:33.929+0000] {logging_mixin.py:151} INFO - [2024-06-13T00:24:33.926+0000] {dagbag.py:346} ERROR - Failed to import: /opt/airflow/dags/data_etl_dag.py
Traceback (most recent call last):
  File "/home/airflow/.local/lib/python3.8/site-packages/airflow/models/dagbag.py", line 342, in parse
    loader.exec_module(new_module)
  File "<frozen importlib._bootstrap_external>", line 843, in exec_module
  File "<frozen importlib._bootstrap>", line 219, in _call_with_frames_removed
  File "/opt/airflow/dags/data_etl_dag.py", line 7, in <module>
    from tasks.parse_hh import get_dataset_with_tags
  File "/opt/airflow/dags/tasks/parse_hh.py", line 3, in <module>
    import fake_useragent
ModuleNotFoundError: No module named 'fake_useragent'
[2024-06-13T00:24:33.931+0000] {processor.py:841} WARNING - No viable dags retrieved from /opt/airflow/dags/data_etl_dag.py
[2024-06-13T00:24:33.945+0000] {processor.py:179} INFO - Processing /opt/airflow/dags/data_etl_dag.py took 0.051 seconds
[2024-06-13T00:25:04.035+0000] {processor.py:157} INFO - Started process (PID=1573) to work on /opt/airflow/dags/data_etl_dag.py
[2024-06-13T00:25:04.036+0000] {processor.py:829} INFO - Processing file /opt/airflow/dags/data_etl_dag.py for tasks to queue
[2024-06-13T00:25:04.037+0000] {logging_mixin.py:151} INFO - [2024-06-13T00:25:04.037+0000] {dagbag.py:536} INFO - Filling up the DagBag from /opt/airflow/dags/data_etl_dag.py
[2024-06-13T00:25:04.066+0000] {logging_mixin.py:151} INFO - [2024-06-13T00:25:04.063+0000] {dagbag.py:346} ERROR - Failed to import: /opt/airflow/dags/data_etl_dag.py
Traceback (most recent call last):
  File "/home/airflow/.local/lib/python3.8/site-packages/airflow/models/dagbag.py", line 342, in parse
    loader.exec_module(new_module)
  File "<frozen importlib._bootstrap_external>", line 843, in exec_module
  File "<frozen importlib._bootstrap>", line 219, in _call_with_frames_removed
  File "/opt/airflow/dags/data_etl_dag.py", line 7, in <module>
    from tasks.parse_hh import get_dataset_with_tags
  File "/opt/airflow/dags/tasks/parse_hh.py", line 3, in <module>
    import fake_useragent
ModuleNotFoundError: No module named 'fake_useragent'
[2024-06-13T00:25:04.067+0000] {processor.py:841} WARNING - No viable dags retrieved from /opt/airflow/dags/data_etl_dag.py
[2024-06-13T00:25:04.079+0000] {processor.py:179} INFO - Processing /opt/airflow/dags/data_etl_dag.py took 0.045 seconds
[2024-06-13T00:25:34.189+0000] {processor.py:157} INFO - Started process (PID=1585) to work on /opt/airflow/dags/data_etl_dag.py
[2024-06-13T00:25:34.190+0000] {processor.py:829} INFO - Processing file /opt/airflow/dags/data_etl_dag.py for tasks to queue
[2024-06-13T00:25:34.191+0000] {logging_mixin.py:151} INFO - [2024-06-13T00:25:34.191+0000] {dagbag.py:536} INFO - Filling up the DagBag from /opt/airflow/dags/data_etl_dag.py
[2024-06-13T00:25:34.222+0000] {logging_mixin.py:151} INFO - [2024-06-13T00:25:34.219+0000] {dagbag.py:346} ERROR - Failed to import: /opt/airflow/dags/data_etl_dag.py
Traceback (most recent call last):
  File "/home/airflow/.local/lib/python3.8/site-packages/airflow/models/dagbag.py", line 342, in parse
    loader.exec_module(new_module)
  File "<frozen importlib._bootstrap_external>", line 843, in exec_module
  File "<frozen importlib._bootstrap>", line 219, in _call_with_frames_removed
  File "/opt/airflow/dags/data_etl_dag.py", line 7, in <module>
    from tasks.parse_hh import get_dataset_with_tags
  File "/opt/airflow/dags/tasks/parse_hh.py", line 3, in <module>
    import fake_useragent
ModuleNotFoundError: No module named 'fake_useragent'
[2024-06-13T00:25:34.223+0000] {processor.py:841} WARNING - No viable dags retrieved from /opt/airflow/dags/data_etl_dag.py
[2024-06-13T00:25:34.236+0000] {processor.py:179} INFO - Processing /opt/airflow/dags/data_etl_dag.py took 0.049 seconds
[2024-06-13T00:26:04.349+0000] {processor.py:157} INFO - Started process (PID=1597) to work on /opt/airflow/dags/data_etl_dag.py
[2024-06-13T00:26:04.350+0000] {processor.py:829} INFO - Processing file /opt/airflow/dags/data_etl_dag.py for tasks to queue
[2024-06-13T00:26:04.350+0000] {logging_mixin.py:151} INFO - [2024-06-13T00:26:04.350+0000] {dagbag.py:536} INFO - Filling up the DagBag from /opt/airflow/dags/data_etl_dag.py
[2024-06-13T00:26:04.386+0000] {logging_mixin.py:151} INFO - [2024-06-13T00:26:04.376+0000] {dagbag.py:346} ERROR - Failed to import: /opt/airflow/dags/data_etl_dag.py
Traceback (most recent call last):
  File "/home/airflow/.local/lib/python3.8/site-packages/airflow/models/dagbag.py", line 342, in parse
    loader.exec_module(new_module)
  File "<frozen importlib._bootstrap_external>", line 843, in exec_module
  File "<frozen importlib._bootstrap>", line 219, in _call_with_frames_removed
  File "/opt/airflow/dags/data_etl_dag.py", line 7, in <module>
    from tasks.parse_hh import get_dataset_with_tags
  File "/opt/airflow/dags/tasks/parse_hh.py", line 3, in <module>
    import fake_useragent
ModuleNotFoundError: No module named 'fake_useragent'
[2024-06-13T00:26:04.387+0000] {processor.py:841} WARNING - No viable dags retrieved from /opt/airflow/dags/data_etl_dag.py
[2024-06-13T00:26:04.401+0000] {processor.py:179} INFO - Processing /opt/airflow/dags/data_etl_dag.py took 0.053 seconds
[2024-06-13T00:26:34.564+0000] {processor.py:157} INFO - Started process (PID=1609) to work on /opt/airflow/dags/data_etl_dag.py
[2024-06-13T00:26:34.564+0000] {processor.py:829} INFO - Processing file /opt/airflow/dags/data_etl_dag.py for tasks to queue
[2024-06-13T00:26:34.565+0000] {logging_mixin.py:151} INFO - [2024-06-13T00:26:34.565+0000] {dagbag.py:536} INFO - Filling up the DagBag from /opt/airflow/dags/data_etl_dag.py
[2024-06-13T00:26:34.598+0000] {logging_mixin.py:151} INFO - [2024-06-13T00:26:34.595+0000] {dagbag.py:346} ERROR - Failed to import: /opt/airflow/dags/data_etl_dag.py
Traceback (most recent call last):
  File "/home/airflow/.local/lib/python3.8/site-packages/airflow/models/dagbag.py", line 342, in parse
    loader.exec_module(new_module)
  File "<frozen importlib._bootstrap_external>", line 843, in exec_module
  File "<frozen importlib._bootstrap>", line 219, in _call_with_frames_removed
  File "/opt/airflow/dags/data_etl_dag.py", line 7, in <module>
    from tasks.parse_hh import get_dataset_with_tags
  File "/opt/airflow/dags/tasks/parse_hh.py", line 3, in <module>
    import fake_useragent
ModuleNotFoundError: No module named 'fake_useragent'
[2024-06-13T00:26:34.600+0000] {processor.py:841} WARNING - No viable dags retrieved from /opt/airflow/dags/data_etl_dag.py
[2024-06-13T00:26:34.614+0000] {processor.py:179} INFO - Processing /opt/airflow/dags/data_etl_dag.py took 0.053 seconds
[2024-06-13T00:27:04.980+0000] {processor.py:157} INFO - Started process (PID=1621) to work on /opt/airflow/dags/data_etl_dag.py
[2024-06-13T00:27:04.981+0000] {processor.py:829} INFO - Processing file /opt/airflow/dags/data_etl_dag.py for tasks to queue
[2024-06-13T00:27:04.981+0000] {logging_mixin.py:151} INFO - [2024-06-13T00:27:04.981+0000] {dagbag.py:536} INFO - Filling up the DagBag from /opt/airflow/dags/data_etl_dag.py
[2024-06-13T00:27:05.015+0000] {logging_mixin.py:151} INFO - [2024-06-13T00:27:05.013+0000] {dagbag.py:346} ERROR - Failed to import: /opt/airflow/dags/data_etl_dag.py
Traceback (most recent call last):
  File "/home/airflow/.local/lib/python3.8/site-packages/airflow/models/dagbag.py", line 342, in parse
    loader.exec_module(new_module)
  File "<frozen importlib._bootstrap_external>", line 843, in exec_module
  File "<frozen importlib._bootstrap>", line 219, in _call_with_frames_removed
  File "/opt/airflow/dags/data_etl_dag.py", line 7, in <module>
    from tasks.parse_hh import get_dataset_with_tags
  File "/opt/airflow/dags/tasks/parse_hh.py", line 3, in <module>
    import fake_useragent
ModuleNotFoundError: No module named 'fake_useragent'
[2024-06-13T00:27:05.016+0000] {processor.py:841} WARNING - No viable dags retrieved from /opt/airflow/dags/data_etl_dag.py
[2024-06-13T00:27:05.029+0000] {processor.py:179} INFO - Processing /opt/airflow/dags/data_etl_dag.py took 0.050 seconds
[2024-06-13T00:27:35.148+0000] {processor.py:157} INFO - Started process (PID=1633) to work on /opt/airflow/dags/data_etl_dag.py
[2024-06-13T00:27:35.149+0000] {processor.py:829} INFO - Processing file /opt/airflow/dags/data_etl_dag.py for tasks to queue
[2024-06-13T00:27:35.150+0000] {logging_mixin.py:151} INFO - [2024-06-13T00:27:35.149+0000] {dagbag.py:536} INFO - Filling up the DagBag from /opt/airflow/dags/data_etl_dag.py
[2024-06-13T00:27:35.172+0000] {logging_mixin.py:151} INFO - [2024-06-13T00:27:35.170+0000] {dagbag.py:346} ERROR - Failed to import: /opt/airflow/dags/data_etl_dag.py
Traceback (most recent call last):
  File "/home/airflow/.local/lib/python3.8/site-packages/airflow/models/dagbag.py", line 342, in parse
    loader.exec_module(new_module)
  File "<frozen importlib._bootstrap_external>", line 843, in exec_module
  File "<frozen importlib._bootstrap>", line 219, in _call_with_frames_removed
  File "/opt/airflow/dags/data_etl_dag.py", line 7, in <module>
    from tasks.parse_hh import get_dataset_with_tags
  File "/opt/airflow/dags/tasks/parse_hh.py", line 3, in <module>
    import fake_useragent
ModuleNotFoundError: No module named 'fake_useragent'
[2024-06-13T00:27:35.174+0000] {processor.py:841} WARNING - No viable dags retrieved from /opt/airflow/dags/data_etl_dag.py
[2024-06-13T00:27:35.186+0000] {processor.py:179} INFO - Processing /opt/airflow/dags/data_etl_dag.py took 0.039 seconds
[2024-06-13T00:28:05.278+0000] {processor.py:157} INFO - Started process (PID=1645) to work on /opt/airflow/dags/data_etl_dag.py
[2024-06-13T00:28:05.278+0000] {processor.py:829} INFO - Processing file /opt/airflow/dags/data_etl_dag.py for tasks to queue
[2024-06-13T00:28:05.279+0000] {logging_mixin.py:151} INFO - [2024-06-13T00:28:05.279+0000] {dagbag.py:536} INFO - Filling up the DagBag from /opt/airflow/dags/data_etl_dag.py
[2024-06-13T00:28:05.309+0000] {logging_mixin.py:151} INFO - [2024-06-13T00:28:05.306+0000] {dagbag.py:346} ERROR - Failed to import: /opt/airflow/dags/data_etl_dag.py
Traceback (most recent call last):
  File "/home/airflow/.local/lib/python3.8/site-packages/airflow/models/dagbag.py", line 342, in parse
    loader.exec_module(new_module)
  File "<frozen importlib._bootstrap_external>", line 843, in exec_module
  File "<frozen importlib._bootstrap>", line 219, in _call_with_frames_removed
  File "/opt/airflow/dags/data_etl_dag.py", line 7, in <module>
    from tasks.parse_hh import get_dataset_with_tags
  File "/opt/airflow/dags/tasks/parse_hh.py", line 3, in <module>
    import fake_useragent
ModuleNotFoundError: No module named 'fake_useragent'
[2024-06-13T00:28:05.310+0000] {processor.py:841} WARNING - No viable dags retrieved from /opt/airflow/dags/data_etl_dag.py
[2024-06-13T00:28:05.325+0000] {processor.py:179} INFO - Processing /opt/airflow/dags/data_etl_dag.py took 0.049 seconds
[2024-06-13T00:28:35.419+0000] {processor.py:157} INFO - Started process (PID=1658) to work on /opt/airflow/dags/data_etl_dag.py
[2024-06-13T00:28:35.420+0000] {processor.py:829} INFO - Processing file /opt/airflow/dags/data_etl_dag.py for tasks to queue
[2024-06-13T00:28:35.420+0000] {logging_mixin.py:151} INFO - [2024-06-13T00:28:35.420+0000] {dagbag.py:536} INFO - Filling up the DagBag from /opt/airflow/dags/data_etl_dag.py
[2024-06-13T00:28:35.447+0000] {logging_mixin.py:151} INFO - [2024-06-13T00:28:35.445+0000] {dagbag.py:346} ERROR - Failed to import: /opt/airflow/dags/data_etl_dag.py
Traceback (most recent call last):
  File "/home/airflow/.local/lib/python3.8/site-packages/airflow/models/dagbag.py", line 342, in parse
    loader.exec_module(new_module)
  File "<frozen importlib._bootstrap_external>", line 843, in exec_module
  File "<frozen importlib._bootstrap>", line 219, in _call_with_frames_removed
  File "/opt/airflow/dags/data_etl_dag.py", line 7, in <module>
    from tasks.parse_hh import get_dataset_with_tags
  File "/opt/airflow/dags/tasks/parse_hh.py", line 3, in <module>
    import fake_useragent
ModuleNotFoundError: No module named 'fake_useragent'
[2024-06-13T00:28:35.448+0000] {processor.py:841} WARNING - No viable dags retrieved from /opt/airflow/dags/data_etl_dag.py
[2024-06-13T00:28:35.459+0000] {processor.py:179} INFO - Processing /opt/airflow/dags/data_etl_dag.py took 0.042 seconds
