[2024-06-16T23:13:17.067+0000] {task_context_logger.py:104} ERROR - Executor reports task instance <TaskInstance: dag_data_etl_v2.get_professions scheduled__2024-06-16T00:00:00+00:00 [queued]> finished (failed) although the task says it's queued. (Info: None) Was the task killed externally?
