[2024-06-17T12:06:44.420+0000] {task_context_logger.py:104} ERROR - Executor reports task instance <TaskInstance: dag_data_etl_v11.get_dataset_with_tags scheduled__2024-06-16T12:00:00+00:00 [queued]> finished (failed) although the task says it's queued. (Info: None) Was the task killed externally?
